Traceback (most recent call last):
  File "C:\Python310\lib\site-packages\jupyter_cache\executors\utils.py", line 51, in single_nb_execution
    executenb(
  File "C:\Python310\lib\site-packages\nbclient\client.py", line 1204, in execute
    return NotebookClient(nb=nb, resources=resources, km=km, **kwargs).execute()
  File "C:\Python310\lib\site-packages\nbclient\util.py", line 84, in wrapped
    return just_run(coro(*args, **kwargs))
  File "C:\Python310\lib\site-packages\nbclient\util.py", line 62, in just_run
    return loop.run_until_complete(coro)
  File "C:\Python310\lib\asyncio\base_events.py", line 641, in run_until_complete
    return future.result()
  File "C:\Python310\lib\site-packages\nbclient\client.py", line 663, in async_execute
    await self.async_execute_cell(
  File "C:\Python310\lib\site-packages\nbclient\client.py", line 965, in async_execute_cell
    await self._check_raise_for_error(cell, cell_index, exec_reply)
  File "C:\Python310\lib\site-packages\nbclient\client.py", line 862, in _check_raise_for_error
    raise CellExecutionError.from_cell_and_msg(cell, exec_reply_content)
nbclient.exceptions.CellExecutionError: An error occurred while executing the following cell:
------------------
# adding serialized data to Stardog (knowledge graph platform)

conn_details = {
  'endpoint': 'http://localhost:5820',
  'username': 'admin',
  'password': 'admin'
}
with stardog.Admin(**conn_details) as admin:
    Jasmin = admin.new_database('Jasmin')

conn = stardog.Connection('Jasmin', **conn_details)

conn.begin()

conn.add(
    stardog.content.File('Jasmin.rdf', stardog.content_types.TURTLE),
)

conn.commit()
------------------

[1;31m---------------------------------------------------------------------------[0m
[1;31mConnectionRefusedError[0m                    Traceback (most recent call last)
File [1;32mC:\Python310\lib\site-packages\urllib3\connection.py:174[0m, in [0;36mHTTPConnection._new_conn[1;34m(self)[0m
[0;32m    173[0m [38;5;28;01mtry[39;00m:
[1;32m--> 174[0m     conn [38;5;241m=[39m connection[38;5;241m.[39mcreate_connection(
[0;32m    175[0m         ([38;5;28mself[39m[38;5;241m.[39m_dns_host, [38;5;28mself[39m[38;5;241m.[39mport), [38;5;28mself[39m[38;5;241m.[39mtimeout, [38;5;241m*[39m[38;5;241m*[39mextra_kw
[0;32m    176[0m     )
[0;32m    178[0m [38;5;28;01mexcept[39;00m SocketTimeout:

File [1;32mC:\Python310\lib\site-packages\urllib3\util\connection.py:95[0m, in [0;36mcreate_connection[1;34m(address, timeout, source_address, socket_options)[0m
[0;32m     94[0m [38;5;28;01mif[39;00m err [38;5;129;01mis[39;00m [38;5;129;01mnot[39;00m [38;5;28;01mNone[39;00m:
[1;32m---> 95[0m     [38;5;28;01mraise[39;00m err
[0;32m     97[0m [38;5;28;01mraise[39;00m socket[38;5;241m.[39merror([38;5;124m"[39m[38;5;124mgetaddrinfo returns an empty list[39m[38;5;124m"[39m)

File [1;32mC:\Python310\lib\site-packages\urllib3\util\connection.py:85[0m, in [0;36mcreate_connection[1;34m(address, timeout, source_address, socket_options)[0m
[0;32m     84[0m     sock[38;5;241m.[39mbind(source_address)
[1;32m---> 85[0m [43msock[49m[38;5;241;43m.[39;49m[43mconnect[49m[43m([49m[43msa[49m[43m)[49m
[0;32m     86[0m [38;5;28;01mreturn[39;00m sock

[1;31mConnectionRefusedError[0m: [WinError 10061] No connection could be made because the target machine actively refused it

During handling of the above exception, another exception occurred:

[1;31mNewConnectionError[0m                        Traceback (most recent call last)
File [1;32mC:\Python310\lib\site-packages\urllib3\connectionpool.py:703[0m, in [0;36mHTTPConnectionPool.urlopen[1;34m(self, method, url, body, headers, retries, redirect, assert_same_host, timeout, pool_timeout, release_conn, chunked, body_pos, **response_kw)[0m
[0;32m    702[0m [38;5;66;03m# Make the request on the httplib connection object.[39;00m
[1;32m--> 703[0m httplib_response [38;5;241m=[39m [38;5;28;43mself[39;49m[38;5;241;43m.[39;49m[43m_make_request[49m[43m([49m
[0;32m    704[0m [43m    [49m[43mconn[49m[43m,[49m
[0;32m    705[0m [43m    [49m[43mmethod[49m[43m,[49m
[0;32m    706[0m [43m    [49m[43murl[49m[43m,[49m
[0;32m    707[0m [43m    [49m[43mtimeout[49m[38;5;241;43m=[39;49m[43mtimeout_obj[49m[43m,[49m
[0;32m    708[0m [43m    [49m[43mbody[49m[38;5;241;43m=[39;49m[43mbody[49m[43m,[49m
[0;32m    709[0m [43m    [49m[43mheaders[49m[38;5;241;43m=[39;49m[43mheaders[49m[43m,[49m
[0;32m    710[0m [43m    [49m[43mchunked[49m[38;5;241;43m=[39;49m[43mchunked[49m[43m,[49m
[0;32m    711[0m [43m[49m[43m)[49m
[0;32m    713[0m [38;5;66;03m# If we're going to release the connection in ``finally:``, then[39;00m
[0;32m    714[0m [38;5;66;03m# the response doesn't need to know about the connection. Otherwise[39;00m
[0;32m    715[0m [38;5;66;03m# it will also try to release it and we'll have a double-release[39;00m
[0;32m    716[0m [38;5;66;03m# mess.[39;00m

File [1;32mC:\Python310\lib\site-packages\urllib3\connectionpool.py:398[0m, in [0;36mHTTPConnectionPool._make_request[1;34m(self, conn, method, url, timeout, chunked, **httplib_request_kw)[0m
[0;32m    397[0m     [38;5;28;01melse[39;00m:
[1;32m--> 398[0m         conn[38;5;241m.[39mrequest(method, url, [38;5;241m*[39m[38;5;241m*[39mhttplib_request_kw)
[0;32m    400[0m [38;5;66;03m# We are swallowing BrokenPipeError (errno.EPIPE) since the server is[39;00m
[0;32m    401[0m [38;5;66;03m# legitimately able to close the connection after sending a valid response.[39;00m
[0;32m    402[0m [38;5;66;03m# With this behaviour, the received response is still readable.[39;00m

File [1;32mC:\Python310\lib\site-packages\urllib3\connection.py:239[0m, in [0;36mHTTPConnection.request[1;34m(self, method, url, body, headers)[0m
[0;32m    238[0m     headers[[38;5;124m"[39m[38;5;124mUser-Agent[39m[38;5;124m"[39m] [38;5;241m=[39m _get_default_user_agent()
[1;32m--> 239[0m [38;5;28;43msuper[39;49m[43m([49m[43mHTTPConnection[49m[43m,[49m[43m [49m[38;5;28;43mself[39;49m[43m)[49m[38;5;241;43m.[39;49m[43mrequest[49m[43m([49m[43mmethod[49m[43m,[49m[43m [49m[43murl[49m[43m,[49m[43m [49m[43mbody[49m[38;5;241;43m=[39;49m[43mbody[49m[43m,[49m[43m [49m[43mheaders[49m[38;5;241;43m=[39;49m[43mheaders[49m[43m)[49m

File [1;32mC:\Python310\lib\http\client.py:1282[0m, in [0;36mHTTPConnection.request[1;34m(self, method, url, body, headers, encode_chunked)[0m
[0;32m   1281[0m [38;5;124;03m"""Send a complete request to the server."""[39;00m
[1;32m-> 1282[0m [38;5;28;43mself[39;49m[38;5;241;43m.[39;49m[43m_send_request[49m[43m([49m[43mmethod[49m[43m,[49m[43m [49m[43murl[49m[43m,[49m[43m [49m[43mbody[49m[43m,[49m[43m [49m[43mheaders[49m[43m,[49m[43m [49m[43mencode_chunked[49m[43m)[49m

File [1;32mC:\Python310\lib\http\client.py:1328[0m, in [0;36mHTTPConnection._send_request[1;34m(self, method, url, body, headers, encode_chunked)[0m
[0;32m   1327[0m     body [38;5;241m=[39m _encode(body, [38;5;124m'[39m[38;5;124mbody[39m[38;5;124m'[39m)
[1;32m-> 1328[0m [38;5;28;43mself[39;49m[38;5;241;43m.[39;49m[43mendheaders[49m[43m([49m[43mbody[49m[43m,[49m[43m [49m[43mencode_chunked[49m[38;5;241;43m=[39;49m[43mencode_chunked[49m[43m)[49m

File [1;32mC:\Python310\lib\http\client.py:1277[0m, in [0;36mHTTPConnection.endheaders[1;34m(self, message_body, encode_chunked)[0m
[0;32m   1276[0m     [38;5;28;01mraise[39;00m CannotSendHeader()
[1;32m-> 1277[0m [38;5;28;43mself[39;49m[38;5;241;43m.[39;49m[43m_send_output[49m[43m([49m[43mmessage_body[49m[43m,[49m[43m [49m[43mencode_chunked[49m[38;5;241;43m=[39;49m[43mencode_chunked[49m[43m)[49m

File [1;32mC:\Python310\lib\http\client.py:1037[0m, in [0;36mHTTPConnection._send_output[1;34m(self, message_body, encode_chunked)[0m
[0;32m   1036[0m [38;5;28;01mdel[39;00m [38;5;28mself[39m[38;5;241m.[39m_buffer[:]
[1;32m-> 1037[0m [38;5;28;43mself[39;49m[38;5;241;43m.[39;49m[43msend[49m[43m([49m[43mmsg[49m[43m)[49m
[0;32m   1039[0m [38;5;28;01mif[39;00m message_body [38;5;129;01mis[39;00m [38;5;129;01mnot[39;00m [38;5;28;01mNone[39;00m:
[0;32m   1040[0m 
[0;32m   1041[0m     [38;5;66;03m# create a consistent interface to message_body[39;00m

File [1;32mC:\Python310\lib\http\client.py:975[0m, in [0;36mHTTPConnection.send[1;34m(self, data)[0m
[0;32m    974[0m [38;5;28;01mif[39;00m [38;5;28mself[39m[38;5;241m.[39mauto_open:
[1;32m--> 975[0m     [38;5;28;43mself[39;49m[38;5;241;43m.[39;49m[43mconnect[49m[43m([49m[43m)[49m
[0;32m    976[0m [38;5;28;01melse[39;00m:

File [1;32mC:\Python310\lib\site-packages\urllib3\connection.py:205[0m, in [0;36mHTTPConnection.connect[1;34m(self)[0m
[0;32m    204[0m [38;5;28;01mdef[39;00m [38;5;21mconnect[39m([38;5;28mself[39m):
[1;32m--> 205[0m     conn [38;5;241m=[39m [38;5;28;43mself[39;49m[38;5;241;43m.[39;49m[43m_new_conn[49m[43m([49m[43m)[49m
[0;32m    206[0m     [38;5;28mself[39m[38;5;241m.[39m_prepare_conn(conn)

File [1;32mC:\Python310\lib\site-packages\urllib3\connection.py:186[0m, in [0;36mHTTPConnection._new_conn[1;34m(self)[0m
[0;32m    185[0m [38;5;28;01mexcept[39;00m SocketError [38;5;28;01mas[39;00m e:
[1;32m--> 186[0m     [38;5;28;01mraise[39;00m NewConnectionError(
[0;32m    187[0m         [38;5;28mself[39m, [38;5;124m"[39m[38;5;124mFailed to establish a new connection: [39m[38;5;132;01m%s[39;00m[38;5;124m"[39m [38;5;241m%[39m e
[0;32m    188[0m     )
[0;32m    190[0m [38;5;28;01mreturn[39;00m conn

[1;31mNewConnectionError[0m: <urllib3.connection.HTTPConnection object at 0x0000018D5C504BE0>: Failed to establish a new connection: [WinError 10061] No connection could be made because the target machine actively refused it

During handling of the above exception, another exception occurred:

[1;31mMaxRetryError[0m                             Traceback (most recent call last)
File [1;32m~\AppData\Roaming\Python\Python310\site-packages\requests\adapters.py:486[0m, in [0;36mHTTPAdapter.send[1;34m(self, request, stream, timeout, verify, cert, proxies)[0m
[0;32m    485[0m [38;5;28;01mtry[39;00m:
[1;32m--> 486[0m     resp [38;5;241m=[39m [43mconn[49m[38;5;241;43m.[39;49m[43murlopen[49m[43m([49m
[0;32m    487[0m [43m        [49m[43mmethod[49m[38;5;241;43m=[39;49m[43mrequest[49m[38;5;241;43m.[39;49m[43mmethod[49m[43m,[49m
[0;32m    488[0m [43m        [49m[43murl[49m[38;5;241;43m=[39;49m[43murl[49m[43m,[49m
[0;32m    489[0m [43m        [49m[43mbody[49m[38;5;241;43m=[39;49m[43mrequest[49m[38;5;241;43m.[39;49m[43mbody[49m[43m,[49m
[0;32m    490[0m [43m        [49m[43mheaders[49m[38;5;241;43m=[39;49m[43mrequest[49m[38;5;241;43m.[39;49m[43mheaders[49m[43m,[49m
[0;32m    491[0m [43m        [49m[43mredirect[49m[38;5;241;43m=[39;49m[38;5;28;43;01mFalse[39;49;00m[43m,[49m
[0;32m    492[0m [43m        [49m[43massert_same_host[49m[38;5;241;43m=[39;49m[38;5;28;43;01mFalse[39;49;00m[43m,[49m
[0;32m    493[0m [43m        [49m[43mpreload_content[49m[38;5;241;43m=[39;49m[38;5;28;43;01mFalse[39;49;00m[43m,[49m
[0;32m    494[0m [43m        [49m[43mdecode_content[49m[38;5;241;43m=[39;49m[38;5;28;43;01mFalse[39;49;00m[43m,[49m
[0;32m    495[0m [43m        [49m[43mretries[49m[38;5;241;43m=[39;49m[38;5;28;43mself[39;49m[38;5;241;43m.[39;49m[43mmax_retries[49m[43m,[49m
[0;32m    496[0m [43m        [49m[43mtimeout[49m[38;5;241;43m=[39;49m[43mtimeout[49m[43m,[49m
[0;32m    497[0m [43m        [49m[43mchunked[49m[38;5;241;43m=[39;49m[43mchunked[49m[43m,[49m
[0;32m    498[0m [43m    [49m[43m)[49m
[0;32m    500[0m [38;5;28;01mexcept[39;00m (ProtocolError, [38;5;167;01mOSError[39;00m) [38;5;28;01mas[39;00m err:

File [1;32mC:\Python310\lib\site-packages\urllib3\connectionpool.py:785[0m, in [0;36mHTTPConnectionPool.urlopen[1;34m(self, method, url, body, headers, retries, redirect, assert_same_host, timeout, pool_timeout, release_conn, chunked, body_pos, **response_kw)[0m
[0;32m    783[0m     e [38;5;241m=[39m ProtocolError([38;5;124m"[39m[38;5;124mConnection aborted.[39m[38;5;124m"[39m, e)
[1;32m--> 785[0m retries [38;5;241m=[39m [43mretries[49m[38;5;241;43m.[39;49m[43mincrement[49m[43m([49m
[0;32m    786[0m [43m    [49m[43mmethod[49m[43m,[49m[43m [49m[43murl[49m[43m,[49m[43m [49m[43merror[49m[38;5;241;43m=[39;49m[43me[49m[43m,[49m[43m [49m[43m_pool[49m[38;5;241;43m=[39;49m[38;5;28;43mself[39;49m[43m,[49m[43m [49m[43m_stacktrace[49m[38;5;241;43m=[39;49m[43msys[49m[38;5;241;43m.[39;49m[43mexc_info[49m[43m([49m[43m)[49m[43m[[49m[38;5;241;43m2[39;49m[43m][49m
[0;32m    787[0m [43m[49m[43m)[49m
[0;32m    788[0m retries[38;5;241m.[39msleep()

File [1;32mC:\Python310\lib\site-packages\urllib3\util\retry.py:592[0m, in [0;36mRetry.increment[1;34m(self, method, url, response, error, _pool, _stacktrace)[0m
[0;32m    591[0m [38;5;28;01mif[39;00m new_retry[38;5;241m.[39mis_exhausted():
[1;32m--> 592[0m     [38;5;28;01mraise[39;00m MaxRetryError(_pool, url, error [38;5;129;01mor[39;00m ResponseError(cause))
[0;32m    594[0m log[38;5;241m.[39mdebug([38;5;124m"[39m[38;5;124mIncremented Retry for (url=[39m[38;5;124m'[39m[38;5;132;01m%s[39;00m[38;5;124m'[39m[38;5;124m): [39m[38;5;132;01m%r[39;00m[38;5;124m"[39m, url, new_retry)

[1;31mMaxRetryError[0m: HTTPConnectionPool(host='localhost', port=5820): Max retries exceeded with url: /admin/databases (Caused by NewConnectionError('<urllib3.connection.HTTPConnection object at 0x0000018D5C504BE0>: Failed to establish a new connection: [WinError 10061] No connection could be made because the target machine actively refused it'))

During handling of the above exception, another exception occurred:

[1;31mConnectionError[0m                           Traceback (most recent call last)
Input [1;32mIn [11][0m, in [0;36m<cell line: 8>[1;34m()[0m
[0;32m      3[0m conn_details [38;5;241m=[39m {
[0;32m      4[0m   [38;5;124m'[39m[38;5;124mendpoint[39m[38;5;124m'[39m: [38;5;124m'[39m[38;5;124mhttp://localhost:5820[39m[38;5;124m'[39m,
[0;32m      5[0m   [38;5;124m'[39m[38;5;124musername[39m[38;5;124m'[39m: [38;5;124m'[39m[38;5;124madmin[39m[38;5;124m'[39m,
[0;32m      6[0m   [38;5;124m'[39m[38;5;124mpassword[39m[38;5;124m'[39m: [38;5;124m'[39m[38;5;124madmin[39m[38;5;124m'[39m
[0;32m      7[0m }
[0;32m      8[0m [38;5;28;01mwith[39;00m stardog[38;5;241m.[39mAdmin([38;5;241m*[39m[38;5;241m*[39mconn_details) [38;5;28;01mas[39;00m admin:
[1;32m----> 9[0m     Jasmin [38;5;241m=[39m [43madmin[49m[38;5;241;43m.[39;49m[43mnew_database[49m[43m([49m[38;5;124;43m'[39;49m[38;5;124;43mJasmin[39;49m[38;5;124;43m'[39;49m[43m)[49m
[0;32m     11[0m conn [38;5;241m=[39m stardog[38;5;241m.[39mConnection([38;5;124m'[39m[38;5;124mJasmin[39m[38;5;124m'[39m, [38;5;241m*[39m[38;5;241m*[39mconn_details)
[0;32m     13[0m conn[38;5;241m.[39mbegin()

File [1;32mC:\Python310\lib\site-packages\stardog\admin.py:163[0m, in [0;36mAdmin.new_database[1;34m(self, name, options, *contents)[0m
[0;32m    156[0m meta [38;5;241m=[39m {
[0;32m    157[0m     [38;5;124m'[39m[38;5;124mdbname[39m[38;5;124m'[39m: name,
[0;32m    158[0m     [38;5;124m'[39m[38;5;124moptions[39m[38;5;124m'[39m: options [38;5;28;01mif[39;00m options [38;5;28;01melse[39;00m {},
[0;32m    159[0m     [38;5;124m'[39m[38;5;124mfiles[39m[38;5;124m'[39m: fmetas
[0;32m    160[0m }
[0;32m    162[0m params[38;5;241m.[39mappend(([38;5;124m'[39m[38;5;124mroot[39m[38;5;124m'[39m, ([38;5;28;01mNone[39;00m, json[38;5;241m.[39mdumps(meta), [38;5;124m'[39m[38;5;124mapplication/json[39m[38;5;124m'[39m)))
[1;32m--> 163[0m [38;5;28;43mself[39;49m[38;5;241;43m.[39;49m[43mclient[49m[38;5;241;43m.[39;49m[43mpost[49m[43m([49m[38;5;124;43m'[39;49m[38;5;124;43m/admin/databases[39;49m[38;5;124;43m'[39;49m[43m,[49m[43m [49m[43mfiles[49m[38;5;241;43m=[39;49m[43mparams[49m[43m)[49m
[0;32m    164[0m [38;5;28;01mreturn[39;00m Database(name, [38;5;28mself[39m[38;5;241m.[39mclient)

File [1;32mC:\Python310\lib\site-packages\stardog\http\client.py:35[0m, in [0;36mClient.post[1;34m(self, path, **kwargs)[0m
[0;32m     34[0m [38;5;28;01mdef[39;00m [38;5;21mpost[39m([38;5;28mself[39m, path, [38;5;241m*[39m[38;5;241m*[39mkwargs):
[1;32m---> 35[0m     [38;5;28;01mreturn[39;00m [38;5;28mself[39m[38;5;241m.[39m__wrap([38;5;28mself[39m[38;5;241m.[39msession[38;5;241m.[39mpost([38;5;28mself[39m[38;5;241m.[39murl [38;5;241m+[39m path, [38;5;241m*[39m[38;5;241m*[39mkwargs))

File [1;32m~\AppData\Roaming\Python\Python310\site-packages\requests\sessions.py:637[0m, in [0;36mSession.post[1;34m(self, url, data, json, **kwargs)[0m
[0;32m    626[0m [38;5;28;01mdef[39;00m [38;5;21mpost[39m([38;5;28mself[39m, url, data[38;5;241m=[39m[38;5;28;01mNone[39;00m, json[38;5;241m=[39m[38;5;28;01mNone[39;00m, [38;5;241m*[39m[38;5;241m*[39mkwargs):
[0;32m    627[0m     [38;5;124mr[39m[38;5;124;03m"""Sends a POST request. Returns :class:`Response` object.[39;00m
[0;32m    628[0m 
[0;32m    629[0m [38;5;124;03m    :param url: URL for the new :class:`Request` object.[39;00m
[1;32m   (...)[0m
[0;32m    634[0m [38;5;124;03m    :rtype: requests.Response[39;00m
[0;32m    635[0m [38;5;124;03m    """[39;00m
[1;32m--> 637[0m     [38;5;28;01mreturn[39;00m [38;5;28mself[39m[38;5;241m.[39mrequest([38;5;124m"[39m[38;5;124mPOST[39m[38;5;124m"[39m, url, data[38;5;241m=[39mdata, json[38;5;241m=[39mjson, [38;5;241m*[39m[38;5;241m*[39mkwargs)

File [1;32m~\AppData\Roaming\Python\Python310\site-packages\requests\sessions.py:589[0m, in [0;36mSession.request[1;34m(self, method, url, params, data, headers, cookies, files, auth, timeout, allow_redirects, proxies, hooks, stream, verify, cert, json)[0m
[0;32m    584[0m send_kwargs [38;5;241m=[39m {
[0;32m    585[0m     [38;5;124m"[39m[38;5;124mtimeout[39m[38;5;124m"[39m: timeout,
[0;32m    586[0m     [38;5;124m"[39m[38;5;124mallow_redirects[39m[38;5;124m"[39m: allow_redirects,
[0;32m    587[0m }
[0;32m    588[0m send_kwargs[38;5;241m.[39mupdate(settings)
[1;32m--> 589[0m resp [38;5;241m=[39m [38;5;28mself[39m[38;5;241m.[39msend(prep, [38;5;241m*[39m[38;5;241m*[39msend_kwargs)
[0;32m    591[0m [38;5;28;01mreturn[39;00m resp

File [1;32m~\AppData\Roaming\Python\Python310\site-packages\requests\sessions.py:703[0m, in [0;36mSession.send[1;34m(self, request, **kwargs)[0m
[0;32m    700[0m start [38;5;241m=[39m preferred_clock()
[0;32m    702[0m [38;5;66;03m# Send the request[39;00m
[1;32m--> 703[0m r [38;5;241m=[39m adapter[38;5;241m.[39msend(request, [38;5;241m*[39m[38;5;241m*[39mkwargs)
[0;32m    705[0m [38;5;66;03m# Total elapsed time of the request (approximately)[39;00m
[0;32m    706[0m elapsed [38;5;241m=[39m preferred_clock() [38;5;241m-[39m start

File [1;32m~\AppData\Roaming\Python\Python310\site-packages\requests\adapters.py:519[0m, in [0;36mHTTPAdapter.send[1;34m(self, request, stream, timeout, verify, cert, proxies)[0m
[0;32m    515[0m     [38;5;28;01mif[39;00m [38;5;28misinstance[39m(e[38;5;241m.[39mreason, _SSLError):
[0;32m    516[0m         [38;5;66;03m# This branch is for urllib3 v1.22 and later.[39;00m
[0;32m    517[0m         [38;5;28;01mraise[39;00m SSLError(e, request[38;5;241m=[39mrequest)
[1;32m--> 519[0m     [38;5;28;01mraise[39;00m [38;5;167;01mConnectionError[39;00m(e, request[38;5;241m=[39mrequest)
[0;32m    521[0m [38;5;28;01mexcept[39;00m ClosedPoolError [38;5;28;01mas[39;00m e:
[0;32m    522[0m     [38;5;28;01mraise[39;00m [38;5;167;01mConnectionError[39;00m(e, request[38;5;241m=[39mrequest)

[1;31mConnectionError[0m: HTTPConnectionPool(host='localhost', port=5820): Max retries exceeded with url: /admin/databases (Caused by NewConnectionError('<urllib3.connection.HTTPConnection object at 0x0000018D5C504BE0>: Failed to establish a new connection: [WinError 10061] No connection could be made because the target machine actively refused it'))
ConnectionError: HTTPConnectionPool(host='localhost', port=5820): Max retries exceeded with url: /admin/databases (Caused by NewConnectionError('<urllib3.connection.HTTPConnection object at 0x0000018D5C504BE0>: Failed to establish a new connection: [WinError 10061] No connection could be made because the target machine actively refused it'))

